Traceback (most recent call last):
  File "/usr/lib/python3/dist-packages/serial/serialposix.py", line 265, in open
    self.fd = os.open(self.portstr, os.O_RDWR | os.O_NOCTTY | os.O_NONBLOCK)
FileNotFoundError: [Errno 2] No such file or directory: '/dev/ttyACM2'

During handling of the above exception, another exception occurred:

Traceback (most recent call last):
  File "uno_read.py", line 11, in <module>
    so_ard = serial.Serial(port = '/dev/ttyACM2', baudrate = 9600, timeout = 0.1)
  File "/usr/lib/python3/dist-packages/serial/serialutil.py", line 240, in __init__
    self.open()
  File "/usr/lib/python3/dist-packages/serial/serialposix.py", line 268, in open
    raise SerialException(msg.errno, "could not open port {}: {}".format(self._port, msg))
serial.serialutil.SerialException: [Errno 2] could not open port /dev/ttyACM2: [Errno 2] No such file or directory: '/dev/ttyACM2'
Traceback (most recent call last):
  File "/usr/lib/python3/dist-packages/serial/serialposix.py", line 265, in open
    self.fd = os.open(self.portstr, os.O_RDWR | os.O_NOCTTY | os.O_NONBLOCK)
FileNotFoundError: [Errno 2] No such file or directory: '/dev/ttyACM2'

During handling of the above exception, another exception occurred:

Traceback (most recent call last):
  File "uno_read.py", line 11, in <module>
    so_ard = serial.Serial(port = '/dev/ttyACM2', baudrate = 9600, timeout = 0.1)
  File "/usr/lib/python3/dist-packages/serial/serialutil.py", line 240, in __init__
    self.open()
  File "/usr/lib/python3/dist-packages/serial/serialposix.py", line 268, in open
    raise SerialException(msg.errno, "could not open port {}: {}".format(self._port, msg))
serial.serialutil.SerialException: [Errno 2] could not open port /dev/ttyACM2: [Errno 2] No such file or directory: '/dev/ttyACM2'
